<?xml version="1.0"?>
<robot name="caster" xmlns:xacro="http://www.ros.org/wiki/xacro">
  <link name="$caster_link">
    <visual>
      <origin xyz="0 0 0" rpy="0 0 0" />
      <geometry>
      <!-- TODO: parametrizar valores -->
      <sphere radius="${caster['radius']}"/>
      </geometry>
    </visual>

    <collision>
      <origin xyz="0 0 0" rpy="0 0 0" />
      <geometry>
      <sphere radius="${caster['radius']}"/>
      </geometry>
    </collision>

    <inertial>
      <mass value="1" />
      <sphere_inertia m="1" r="${wheel['radius']}" />
    </inertial>
  </link>

  <gazebo reference="caster_link">
    <mu1 value="0.0"/>
    <mu2 value="1.0"/>
    <kp  value="10000000.0"/>
    <kd  value="1.0" />
    <fdir1 value="0 1 0"/>
    <minDepth value="0.001"/>
    <material>Gazebo/Black</material>
    <turnGravityOff>false</turnGravityOff>
  </gazebo>

  <joint name="caster_joint" type="continuous">
    <parent link="base_link"/>
    <child link="$caster_link"/>
    <origin xyz="0.35 0 -${caster['radius']}" rpy="0 0 0"/>
    <axis xyz="0 1 0" />
    <joint_properties damping="0.0" friction="0.0"/>
  </joint>
</robot>